<?xml version="1.0" encoding="UTF-8"?>
<testng-results ignored="0" total="1" passed="0" failed="1" skipped="0">
  <reporter-output>
  </reporter-output>
  <suite started-at="2024-04-11T15:44:58 IST" name="Suite" finished-at="2024-04-11T15:45:04 IST" duration-ms="6372">
    <groups>
    </groups>
    <test started-at="2024-04-11T15:44:58 IST" name="Test" finished-at="2024-04-11T15:45:04 IST" duration-ms="6372">
      <class name="testcases.NegativeScenarios">
        <test-method is-config="true" signature="initialization()[pri:0, instance:testcases.NegativeScenarios@77f1baf5]" started-at="2024-04-11T15:44:57 IST" name="initialization" finished-at="2024-04-11T15:44:58 IST" duration-ms="107" status="PASS">
          <reporter-output>
          </reporter-output>
        </test-method> <!-- initialization -->
        <test-method is-config="true" signature="navigateToUrl()[pri:0, instance:testcases.NegativeScenarios@77f1baf5]" started-at="2024-04-11T15:44:58 IST" name="navigateToUrl" finished-at="2024-04-11T15:45:03 IST" duration-ms="5198" status="PASS">
          <reporter-output>
          </reporter-output>
        </test-method> <!-- navigateToUrl -->
        <test-method signature="myTest(java.lang.String,java.lang.String)[pri:0, instance:testcases.NegativeScenarios@77f1baf5]" started-at="2024-04-11T15:45:03 IST" name="myTest" data-provider="invalidLoginOptions" finished-at="2024-04-11T15:45:04 IST" duration-ms="939" status="FAIL">
          <params>
            <param index="0">
              <value>
                <![CDATA[locked_out_user]]>
              </value>
            </param>
            <param index="1">
              <value>
                <![CDATA[secret_sauce]]>
              </value>
            </param>
          </params>
          <exception class="java.lang.AssertionError">
            <message>
              <![CDATA[Error message for trying to login with Locked out user is not matching expected [true] but found [false]]]>
            </message>
            <full-stacktrace>
              <![CDATA[java.lang.AssertionError: Error message for trying to login with Locked out user is not matching expected [true] but found [false]
at org.testng.Assert.fail(Assert.java:111)
at org.testng.Assert.failNotEquals(Assert.java:1578)
at org.testng.Assert.assertTrue(Assert.java:57)
at testcases.NegativeScenarios.myTest(NegativeScenarios.java:27)
at java.base/jdk.internal.reflect.DirectMethodHandleAccessor.invoke(DirectMethodHandleAccessor.java:103)
at java.base/java.lang.reflect.Method.invoke(Method.java:580)
at org.testng.internal.invokers.MethodInvocationHelper.invokeMethod(MethodInvocationHelper.java:139)
at org.testng.internal.invokers.TestInvoker.invokeMethod(TestInvoker.java:664)
at org.testng.internal.invokers.TestInvoker.invokeTestMethod(TestInvoker.java:228)
at org.testng.internal.invokers.MethodRunner.runInSequence(MethodRunner.java:63)
at org.testng.internal.invokers.TestInvoker$MethodInvocationAgent.invoke(TestInvoker.java:961)
at org.testng.internal.invokers.TestInvoker.invokeTestMethods(TestInvoker.java:201)
at org.testng.internal.invokers.TestMethodWorker.invokeTestMethods(TestMethodWorker.java:148)
at org.testng.internal.invokers.TestMethodWorker.run(TestMethodWorker.java:128)
at java.base/java.util.ArrayList.forEach(ArrayList.java:1597)
at org.testng.TestRunner.privateRun(TestRunner.java:819)
at org.testng.TestRunner.run(TestRunner.java:619)
at org.testng.SuiteRunner.runTest(SuiteRunner.java:443)
at org.testng.SuiteRunner.runSequentially(SuiteRunner.java:437)
at org.testng.SuiteRunner.privateRun(SuiteRunner.java:397)
at org.testng.SuiteRunner.run(SuiteRunner.java:336)
at org.testng.SuiteRunnerWorker.runSuite(SuiteRunnerWorker.java:52)
at org.testng.SuiteRunnerWorker.run(SuiteRunnerWorker.java:95)
at org.testng.TestNG.runSuitesSequentially(TestNG.java:1301)
at org.testng.TestNG.runSuitesLocally(TestNG.java:1228)
at org.testng.TestNG.runSuites(TestNG.java:1134)
at org.testng.TestNG.run(TestNG.java:1101)
at org.testng.remote.AbstractRemoteTestNG.run(AbstractRemoteTestNG.java:115)
at org.testng.remote.RemoteTestNG.initAndRun(RemoteTestNG.java:251)
at org.testng.remote.RemoteTestNG.main(RemoteTestNG.java:77)
]]>
            </full-stacktrace>
          </exception> <!-- java.lang.AssertionError -->
          <reporter-output>
          </reporter-output>
        </test-method> <!-- myTest -->
        <test-method is-config="true" signature="cleanUp()[pri:0, instance:testcases.NegativeScenarios@77f1baf5]" started-at="2024-04-11T15:45:04 IST" name="cleanUp" finished-at="2024-04-11T15:45:04 IST" duration-ms="184" status="PASS">
          <reporter-output>
          </reporter-output>
        </test-method> <!-- cleanUp -->
      </class> <!-- testcases.NegativeScenarios -->
    </test> <!-- Test -->
  </suite> <!-- Suite -->
</testng-results>
